2025-05-07 11:16:00,661 ERROR scheduler Skipped queueing frappe.integrations.doctype.google_calendar.google_calendar.sync because it was found in queue for erpnext.localhost
2025-05-07 11:16:00,663 ERROR scheduler Skipped queueing frappe.email.doctype.newsletter.newsletter.send_scheduled_email because it was found in queue for erpnext.localhost
2025-05-07 11:16:00,668 ERROR scheduler Skipped queueing frappe.automation.doctype.reminder.reminder.send_reminders because it was found in queue for erpnext.localhost
2025-05-07 11:16:00,670 ERROR scheduler Skipped queueing frappe.monitor.flush because it was found in queue for erpnext.localhost
2025-05-07 11:16:00,672 ERROR scheduler Skipped queueing erpnext.manufacturing.doctype.bom_update_log.bom_update_log.resume_bom_cost_update_jobs because it was found in queue for erpnext.localhost
2025-05-07 11:16:00,674 ERROR scheduler Skipped queueing frappe.utils.global_search.sync_global_search because it was found in queue for erpnext.localhost
2025-05-07 11:16:00,676 ERROR scheduler Skipped queueing frappe.model.utils.link_count.update_link_count because it was found in queue for erpnext.localhost
2025-05-07 11:16:00,677 ERROR scheduler Skipped queueing frappe.desk.form.document_follow.send_hourly_updates because it was found in queue for erpnext.localhost
2025-05-07 11:16:00,682 ERROR scheduler Skipped queueing erpnext.stock.doctype.repost_item_valuation.repost_item_valuation.repost_entries because it was found in queue for erpnext.localhost
2025-05-07 11:16:00,684 ERROR scheduler Skipped queueing frappe.desk.page.backups.backups.delete_downloadable_backups because it was found in queue for erpnext.localhost
2025-05-07 11:16:00,686 ERROR scheduler Skipped queueing erpnext.utilities.doctype.video.video.update_youtube_data because it was found in queue for erpnext.localhost
2025-05-07 11:16:00,688 ERROR scheduler Skipped queueing frappe.oauth.delete_oauth2_data because it was found in queue for erpnext.localhost
2025-05-07 11:16:00,691 ERROR scheduler Skipped queueing frappe.email.queue.flush because it was found in queue for erpnext.localhost
2025-05-07 11:16:00,693 ERROR scheduler Skipped queueing frappe.email.doctype.email_account.email_account.pull because it was found in queue for erpnext.localhost
2025-05-07 11:16:00,695 ERROR scheduler Skipped queueing frappe.model.utils.user_settings.sync_user_settings because it was found in queue for erpnext.localhost
2025-05-07 11:16:00,698 ERROR scheduler Skipped queueing frappe.website.doctype.personal_data_deletion_request.personal_data_deletion_request.process_data_deletion_request because it was found in queue for erpnext.localhost
2025-05-07 11:16:00,699 ERROR scheduler Skipped queueing erpnext.projects.doctype.project.project.collect_project_status because it was found in queue for erpnext.localhost
2025-05-07 11:16:00,701 ERROR scheduler Skipped queueing erpnext.utilities.bulk_transaction.retry because it was found in queue for erpnext.localhost
2025-06-01 02:48:00,249 ERROR scheduler Exception in Enqueue Events for Site erpnext.localhost
Traceback (most recent call last):
  File "/home/zotina/Documents/etude/S6/evaluation/python/frappe-bench/env/lib/python3.12/site-packages/pymysql/connections.py", line 649, in connect
    sock = socket.create_connection(
           ^^^^^^^^^^^^^^^^^^^^^^^^^
  File "/usr/lib/python3.12/socket.py", line 852, in create_connection
    raise exceptions[0]
  File "/usr/lib/python3.12/socket.py", line 837, in create_connection
    sock.connect(sa)
ConnectionRefusedError: [Errno 111] Connection refused

During handling of the above exception, another exception occurred:

Traceback (most recent call last):
  File "/home/zotina/Documents/etude/S6/evaluation/python/frappe-bench/apps/frappe/frappe/utils/scheduler.py", line 117, in enqueue_events_for_site
    if is_scheduler_inactive():
       ^^^^^^^^^^^^^^^^^^^^^^^
  File "/home/zotina/Documents/etude/S6/evaluation/python/frappe-bench/apps/frappe/frappe/utils/scheduler.py", line 161, in is_scheduler_inactive
    if is_scheduler_disabled(verbose=verbose):
       ^^^^^^^^^^^^^^^^^^^^^^^^^^^^^^^^^^^^^^
  File "/home/zotina/Documents/etude/S6/evaluation/python/frappe-bench/apps/frappe/frappe/utils/scheduler.py", line 174, in is_scheduler_disabled
    frappe.db.get_single_value("System Settings", "enable_scheduler")
  File "/home/zotina/Documents/etude/S6/evaluation/python/frappe-bench/apps/frappe/frappe/database/database.py", line 884, in get_single_value
    ).run()
      ^^^^^
  File "/home/zotina/Documents/etude/S6/evaluation/python/frappe-bench/apps/frappe/frappe/query_builder/utils.py", line 80, in execute_query
    result = frappe.db.sql(query, params, *args, **kwargs)  # nosemgrep
             ^^^^^^^^^^^^^^^^^^^^^^^^^^^^^^^^^^^^^^^^^^^^^
  File "/home/zotina/Documents/etude/S6/evaluation/python/frappe-bench/apps/frappe/frappe/database/database.py", line 237, in sql
    self.connect()
  File "/home/zotina/Documents/etude/S6/evaluation/python/frappe-bench/apps/frappe/frappe/database/database.py", line 135, in connect
    self.get_connection()
  File "/home/zotina/Documents/etude/S6/evaluation/python/frappe-bench/apps/frappe/frappe/database/mariadb/database.py", line 105, in get_connection
    conn = self._get_connection()
           ^^^^^^^^^^^^^^^^^^^^^^
  File "/home/zotina/Documents/etude/S6/evaluation/python/frappe-bench/apps/frappe/frappe/database/mariadb/database.py", line 111, in _get_connection
    return self.create_connection()
           ^^^^^^^^^^^^^^^^^^^^^^^^
  File "/home/zotina/Documents/etude/S6/evaluation/python/frappe-bench/apps/frappe/frappe/database/mariadb/database.py", line 114, in create_connection
    return pymysql.connect(**self.get_connection_settings())
           ^^^^^^^^^^^^^^^^^^^^^^^^^^^^^^^^^^^^^^^^^^^^^^^^^
  File "/home/zotina/Documents/etude/S6/evaluation/python/frappe-bench/env/lib/python3.12/site-packages/pymysql/connections.py", line 361, in __init__
    self.connect()
  File "/home/zotina/Documents/etude/S6/evaluation/python/frappe-bench/env/lib/python3.12/site-packages/pymysql/connections.py", line 716, in connect
    raise exc
pymysql.err.OperationalError: (2003, "Can't connect to MySQL server on '127.0.0.1' ([Errno 111] Connection refused)")
